Exception on /uploaded [POST]
Traceback (most recent call last):
  File "C:\Users\Gustavo\Anaconda3\lib\site-packages\flask\app.py", line 1817, in wsgi_app
    response = self.full_dispatch_request()
  File "C:\Users\Gustavo\Anaconda3\lib\site-packages\flask\app.py", line 1477, in full_dispatch_request
    rv = self.handle_user_exception(e)
  File "C:\Users\Gustavo\Anaconda3\lib\site-packages\flask\app.py", line 1381, in handle_user_exception
    reraise(exc_type, exc_value, tb)
  File "C:\Users\Gustavo\Anaconda3\lib\site-packages\flask\_compat.py", line 33, in reraise
    raise value
  File "C:\Users\Gustavo\Anaconda3\lib\site-packages\flask\app.py", line 1475, in full_dispatch_request
    rv = self.dispatch_request()
  File "C:\Users\Gustavo\Anaconda3\lib\site-packages\flask\app.py", line 1461, in dispatch_request
    return self.view_functions[rule.endpoint](**req.view_args)
  File "C:\Users\Gustavo\WebApps\AI_Startup_Prototype\flaskSaaS-master\app\views\main.py", line 27, in upload_file
    img = image.load_img(path, target_size=(224,224))
  File "C:\Users\Gustavo\Anaconda3\lib\site-packages\keras_preprocessing\image\utils.py", line 110, in load_img
    img = pil_image.open(path)
  File "C:\Users\Gustavo\Anaconda3\lib\site-packages\PIL\Image.py", line 2634, in open
    fp = builtins.open(filename, "rb")
FileNotFoundError: [Errno 2] No such file or directory: '/Users/Gustavo/WebApps/AI_Startup_Prototype/flaskSaaS-master/app/forms\\CV SSR dotNet y SQL Server Dev Gustavo Adolfo Castillo Mora Jun 2019.pdf'
